//problem  5
//5.Wrap the program to Q3 inside a method which throws your custom exception  

import java.util.*;

class CustomException extends Exception {
    public CustomException(String message) {
        super(message);
    }
}

public class DAY16_PQ5 {
    public static void main(String[] args) {
        try {
            processInput();
        } catch (CustomException e) {
            System.out.println(e.getMessage());
        }
    }

    public static void processInput() throws CustomException {
        boolean flag = true;
        int[] marks = { 7, 56, 6 };
        Scanner sc = new Scanner(System.in);
        int i = 0;
        final int MAX_RETRIES = 5;

        while (flag && i < MAX_RETRIES) {
            try {
                System.out.println("Enter the value of index");
                int index = sc.nextInt();

                if (index < 0 || index >= marks.length) {
                    throw new IndexOutOfBoundsException("Index is out of bounds");
                }

                System.out.println("The value of marks[index] is " + marks[index]);
                flag = false;
            } catch (InputMismatchException e) {
                System.out.println("Invalid input. Please enter a valid integer.");
                sc.next(); // Consume the invalid input to avoid an infinite loop
            } catch (IndexOutOfBoundsException e) {
                System.out.println("Invalid Index. Index should be between 0 and " + (marks.length - 1));
                i++;
            }
        }

        if (i >= MAX_RETRIES) {
            throw new CustomException("Max retries reached. Exiting program.");
        }
    }
}

